Workbook

Sheet Dashboard
A1: Nvidia — Intrinsic Value Dashboard
A3: Calculation integrity | B3: Formula workbook; recalculated and error-scanned in the run log
A4: Decision readiness | B4: SCREEN-GRADE — public actuals plus analyst forecast/WACC assumptions
A6: Valuation date | B6: 2026-08-04 | F6: Core method | G6: 6-year FCFF, mid-year convention, Gordon growth
A7: Current price | B7: ='Control Panel'!$B$12 -> 211.94 | F7: Current price source | G7: https://stockanalysis.com/stocks/nvda/
B8: Downside | C8: Base | D8: Upside
A9: WACC | B9: =B43 -> 0.121353 | C9: =J43 -> 0.106353 | D9: =R43 -> 0.098853
A10: Terminal growth | B10: =B44 -> 0.025 | C10: =J44 -> 0.03 | D10: =R44 -> 0.035
A11: Revenue CAGR | B11: =((1+B26)*(1+C26)*(1+D26)*(1+E26)*(1+F26)*(1+G26))^(1/6)-1 -> 0.12208655 | C11: =((1+J26)*(1+K26)*(1+L26)*(1+M26)*(1+N26)*(1+O26))^(1/6)-1 -> 0.20355008 | D11: =((1+R26)*(1+S26)*(1+T26)*(1+U26)*(1+V26)*(1+W26))^(1/6)-1 -> 0.2636404
A12: Enterprise value | B12: =B49 -> 1701384.8 | C12: =J49 -> 3537229.9 | D12: =R49 -> 6042825
A13: Value per share | B13: =B57 -> 72.55171 | C13: =J57 -> 147.81903 | D13: =R57 -> 250.54524
A14: Premium / (discount) | B14: =B59 -> -0.65767807 | C14: =J59 -> -0.30254305 | D14: =R59 -> 0.18215176
A15: Terminal value / EV | B15: =B60 -> 0.59525005 | C15: =J60 -> 0.68419427 | D15: =R60 -> 0.74755119
A17: Reverse DCF
A18: Uniform growth uplift vs base | C18: 0.089623863
A19: Market-implied six-year revenue CAGR | C19: =((1+Z26)*(1+AA26)*(1+AB26)*(1+AC26)*(1+AD26)*(1+AE26))^(1/6)-1 -> 0.29338566
A20: Reverse-DCF value per share | C20: =Z57 -> 211.94
B24: Downside | J24: Base | R24: Upside | Z24: Reverse DCF
B25: ='Control Panel'!B$18 -> 2027E | C25: ='Control Panel'!C$18 -> 2028E | D25: ='Control Panel'!D$18 -> 2029E | E25: ='Control Panel'!E$18 -> 2030E | F25: ='Control Panel'!F$18 -> 2031E | G25: ='Control Panel'!G$18 -> 2032E | J25: ='Control Panel'!B$18 -> 2027E | K25: ='Control Panel'!C$18 -> 2028E | L25: ='Control Panel'!D$18 -> 2029E | M25: ='Control Panel'!E$18 -> 2030E | N25: ='Control Panel'!F$18 -> 2031E | O25: ='Control Panel'!G$18 -> 2032E | R25: ='Control Panel'!B$18 -> 2027E | S25: ='Control Panel'!C$18 -> 2028E | T25: ='Control Panel'!D$18 -> 2029E | U25: ='Control Panel'!E$18 -> 2030E | V25: ='Control Panel'!F$18 -> 2031E | W25: ='Control Panel'!G$18 -> 2032E | Z25: ='Control Panel'!B$18 -> 2027E | AA25: ='Control Panel'!C$18 -> 2028E | AB25: ='Control Panel'!D$18 -> 2029E | AC25: ='Control Panel'!E$18 -> 2030E | AD25: ='Control Panel'!F$18 -> 2031E | AE25: ='Control Panel'!G$18 -> 2032E
A26: Revenue growth | B26: ='Control Panel'!B$22 -> 0.22 | C26: ='Control Panel'!C$22 -> 0.16 | D26: ='Control Panel'!D$22 -> 0.12 | E26: ='Control Panel'!E$22 -> 0.1 | F26: ='Control Panel'!F$22 -> 0.08 | G26: ='Control Panel'!G$22 -> 0.06 | J26: ='Control Panel'!B$21 -> 0.36 | K26: ='Control Panel'!C$21 -> 0.27 | L26: ='Control Panel'!D$21 -> 0.21 | M26: ='Control Panel'!E$21 -> 0.17 | N26: ='Control Panel'!F$21 -> 0.13 | O26: ='Control Panel'!G$21 -> 0.1 | R26: ='Control Panel'!B$23 -> 0.45 | S26: ='Control Panel'!C$23 -> 0.36 | T26: ='Control Panel'!D$23 -> 0.28 | U26: ='Control Panel'!E$23 -> 0.22 | V26: ='Control Panel'!F$23 -> 0.17 | W26: ='Control Panel'!G$23 -> 0.13 | Z26: ='Control Panel'!B$21+$C$18 -> 0.44962386 | AA26: ='Control Panel'!C$21+$C$18 -> 0.35962386 | AB26: ='Control Panel'!D$21+$C$18 -> 0.29962386 | AC26: ='Control Panel'!E$21+$C$18 -> 0.25962386 | AD26: ='Control Panel'!F$21+$C$18 -> 0.21962386 | AE26: ='Control Panel'!G$21+$C$18 -> 0.18962386
A27: Revenue | B27: ='Historical Financials'!$D$6*(1+B26) -> 309259.02 | C27: =B27*(1+C26) -> 358740.46 | D27: =C27*(1+D26) -> 401789.32 | E27: =D27*(1+E26) -> 441968.25 | F27: =E27*(1+F26) -> 477325.71 | G27: =F27*(1+G26) -> 505965.25 | J27: ='Historical Financials'!$D$6*(1+J26) -> 344747.76 | K27: =J27*(1+K26) -> 437829.66 | L27: =K27*(1+L26) -> 529773.88 | M27: =L27*(1+M26) -> 619835.44 | N27: =M27*(1+N26) -> 700414.05 | O27: =N27*(1+O26) -> 770455.46 | R27: ='Historical Financials'!$D$6*(1+R26) -> 367561.95 | S27: =R27*(1+S26) -> 499884.25 | T27: =S27*(1+T26) -> 639851.84 | U27: =T27*(1+U26) -> 780619.25 | V27: =U27*(1+V26) -> 913324.52 | W27: =V27*(1+W26) -> 1032056.7 | Z27: ='Historical Financials'!$D$6*(1+Z26) -> 367466.6 | AA27: =Z27*(1+AA26) -> 499616.36 | AB27: =AA27*(1+AB26) -> 649313.35 | AC27: =AB27*(1+AC26) -> 817890.59 | AD27: =AC27*(1+AD26) -> 997518.88 | AE27: =AD27*(1+AE26) -> 1186672.3
A28: EBIT margin | B28: ='Control Panel'!B$32 -> 0.57 | C28: ='Control Panel'!C$32 -> 0.55 | D28: ='Control Panel'!D$32 -> 0.53 | E28: ='Control Panel'!E$32 -> 0.51 | F28: ='Control Panel'!F$32 -> 0.49 | G28: ='Control Panel'!G$32 -> 0.48 | J28: ='Control Panel'!B$31 -> 0.63 | K28: ='Control Panel'!C$31 -> 0.62 | L28: ='Control Panel'!D$31 -> 0.6 | M28: ='Control Panel'!E$31 -> 0.58 | N28: ='Control Panel'!F$31 -> 0.56 | O28: ='Control Panel'!G$31 -> 0.54 | R28: ='Control Panel'!B$33 -> 0.66 | S28: ='Control Panel'!C$33 -> 0.66 | T28: ='Control Panel'!D$33 -> 0.64 | U28: ='Control Panel'!E$33 -> 0.62 | V28: ='Control Panel'!F$33 -> 0.6 | W28: ='Control Panel'!G$33 -> 0.59 | Z28: ='Control Panel'!B$31 -> 0.63 | AA28: ='Control Panel'!C$31 -> 0.62 | AB28: ='Control Panel'!D$31 -> 0.6 | AC28: ='Control Panel'!E$31 -> 0.58 | AD28: ='Control Panel'!F$31 -> 0.56 | AE28: ='Control Panel'!G$31 -> 0.54
A29: EBIT | B29: =B27*B28 -> 176277.64 | C29: =C27*C28 -> 197307.25 | D29: =D27*D28 -> 212948.34 | E29: =E27*E28 -> 225403.81 | F29: =F27*F28 -> 233889.6 | G29: =G27*G28 -> 242863.32 | J29: =J27*J28 -> 217191.09 | K29: =K27*K28 -> 271454.39 | L29: =L27*L28 -> 317864.33 | M29: =M27*M28 -> 359504.56 | N29: =N27*N28 -> 392231.87 | O29: =O27*O28 -> 416045.95 | R29: =R27*R28 -> 242590.89 | S29: =S27*S28 -> 329923.61 | T29: =T27*T28 -> 409505.18 | U29: =U27*U28 -> 483983.93 | V29: =V27*V28 -> 547994.71 | W29: =W27*W28 -> 608913.46 | Z29: =Z27*Z28 -> 231503.96 | AA29: =AA27*AA28 -> 309762.14 | AB29: =AB27*AB28 -> 389588.01 | AC29: =AC27*AC28 -> 474376.54 | AD29: =AD27*AD28 -> 558610.57 | AE29: =AE27*AE28 -> 640803.02
A30: Tax rate | B30: ='Control Panel'!B$52 -> 0.18 | C30: ='Control Panel'!C$52 -> 0.18 | D30: ='Control Panel'!D$52 -> 0.18 | E30: ='Control Panel'!E$52 -> 0.18 | F30: ='Control Panel'!F$52 -> 0.18 | G30: ='Control Panel'!G$52 -> 0.18 | J30: ='Control Panel'!B$51 -> 0.17 | K30: ='Control Panel'!C$51 -> 0.17 | L30: ='Control Panel'!D$51 -> 0.17 | M30: ='Control Panel'!E$51 -> 0.17 | N30: ='Control Panel'!F$51 -> 0.17 | O30: ='Control Panel'!G$51 -> 0.17 | R30: ='Control Panel'!B$53 -> 0.16 | S30: ='Control Panel'!C$53 -> 0.16 | T30: ='Control Panel'!D$53 -> 0.16 | U30: ='Control Panel'!E$53 -> 0.16 | V30: ='Control Panel'!F$53 -> 0.16 | W30: ='Control Panel'!G$53 -> 0.16 | Z30: ='Control Panel'!B$51 -> 0.17 | AA30: ='Control Panel'!C$51 -> 0.17 | AB30: ='Control Panel'!D$51 -> 0.17 | AC30: ='Control Panel'!E$51 -> 0.17 | AD30: ='Control Panel'!F$51 -> 0.17 | AE30: ='Control Panel'!G$51 -> 0.17
A31: NOPAT | B31: =B29*(1-B30) -> 144547.67 | C31: =C29*(1-C30) -> 161791.95 | D31: =D29*(1-D30) -> 174617.64 | E31: =E29*(1-E30) -> 184831.12 | F31: =F29*(1-F30) -> 191789.47 | G31: =G29*(1-G30) -> 199147.92 | J31: =J29*(1-J30) -> 180268.6 | K31: =K29*(1-K30) -> 225307.14 | L31: =L29*(1-L30) -> 263827.39 | M31: =M29*(1-M30) -> 298388.78 | N31: =N29*(1-N30) -> 325552.45 | O31: =O29*(1-O30) -> 345318.14 | R31: =R29*(1-R30) -> 203776.35 | S31: =S29*(1-S30) -> 277135.83 | T31: =T29*(1-T30) -> 343984.35 | U31: =U29*(1-U30) -> 406546.5 | V31: =V29*(1-V30) -> 460315.56 | W31: =W29*(1-W30) -> 511487.3 | Z31: =Z29*(1-Z30) -> 192148.29 | AA31: =AA29*(1-AA30) -> 257102.58 | AB31: =AB29*(1-AB30) -> 323358.05 | AC31: =AC29*(1-AC30) -> 393732.53 | AD31: =AD29*(1-AD30) -> 463646.77 | AE31: =AE29*(1-AE30) -> 531866.51
A32: D&A / revenue | B32: ='Control Panel'!B$37 -> 0.015 | C32: ='Control Panel'!C$37 -> 0.017 | D32: ='Control Panel'!D$37 -> 0.019 | E32: ='Control Panel'!E$37 -> 0.021 | F32: ='Control Panel'!F$37 -> 0.022 | G32: ='Control Panel'!G$37 -> 0.022 | J32: ='Control Panel'!B$36 -> 0.015 | K32: ='Control Panel'!C$36 -> 0.017 | L32: ='Control Panel'!D$36 -> 0.019 | M32: ='Control Panel'!E$36 -> 0.021 | N32: ='Control Panel'!F$36 -> 0.022 | O32: ='Control Panel'!G$36 -> 0.022 | R32: ='Control Panel'!B$38 -> 0.015 | S32: ='Control Panel'!C$38 -> 0.017 | T32: ='Control Panel'!D$38 -> 0.019 | U32: ='Control Panel'!E$38 -> 0.021 | V32: ='Control Panel'!F$38 -> 0.022 | W32: ='Control Panel'!G$38 -> 0.022 | Z32: ='Control Panel'!B$36 -> 0.015 | AA32: ='Control Panel'!C$36 -> 0.017 | AB32: ='Control Panel'!D$36 -> 0.019 | AC32: ='Control Panel'!E$36 -> 0.021 | AD32: ='Control Panel'!F$36 -> 0.022 | AE32: ='Control Panel'!G$36 -> 0.022
A33: D&A | B33: =B27*B32 -> 4638.8853 | C33: =C27*C32 -> 6098.5879 | D33: =D27*D32 -> 7633.9971 | E33: =E27*E32 -> 9281.3333 | F33: =F27*F32 -> 10501.166 | G33: =G27*G32 -> 11131.236 | J33: =J27*J32 -> 5171.2164 | K33: =K27*K32 -> 7443.1041 | L33: =L27*L32 -> 10065.704 | M33: =M27*M32 -> 13016.544 | N33: =N27*N32 -> 15409.109 | O33: =O27*O32 -> 16950.02 | R33: =R27*R32 -> 5513.4293 | S33: =S27*S32 -> 8498.0323 | T33: =T27*T32 -> 12157.185 | U33: =U27*U32 -> 16393.004 | V33: =V27*V32 -> 20093.139 | W33: =W27*W32 -> 22705.248 | Z33: =Z27*Z32 -> 5511.999 | AA33: =AA27*AA32 -> 8493.4782 | AB33: =AB27*AB32 -> 12336.954 | AC33: =AC27*AC32 -> 17175.702 | AD33: =AD27*AD32 -> 21945.415 | AE33: =AE27*AE32 -> 26106.79
A34: Capex / revenue | B34: ='Control Panel'!B$42 -> 0.04 | C34: ='Control Panel'!C$42 -> 0.04 | D34: ='Control Panel'!D$42 -> 0.04 | E34: ='Control Panel'!E$42 -> 0.04 | F34: ='Control Panel'!F$42 -> 0.04 | G34: ='Control Panel'!G$42 -> 0.04 | J34: ='Control Panel'!B$41 -> 0.03 | K34: ='Control Panel'!C$41 -> 0.032 | L34: ='Control Panel'!D$41 -> 0.034 | M34: ='Control Panel'!E$41 -> 0.035 | N34: ='Control Panel'!F$41 -> 0.035 | O34: ='Control Panel'!G$41 -> 0.035 | R34: ='Control Panel'!B$43 -> 0.028 | S34: ='Control Panel'!C$43 -> 0.03 | T34: ='Control Panel'!D$43 -> 0.032 | U34: ='Control Panel'!E$43 -> 0.033 | V34: ='Control Panel'!F$43 -> 0.033 | W34: ='Control Panel'!G$43 -> 0.033 | Z34: ='Control Panel'!B$41 -> 0.03 | AA34: ='Control Panel'!C$41 -> 0.032 | AB34: ='Control Panel'!D$41 -> 0.034 | AC34: ='Control Panel'!E$41 -> 0.035 | AD34: ='Control Panel'!F$41 -> 0.035 | AE34: ='Control Panel'!G$41 -> 0.035
A35: Capex | B35: =B27*B34 -> 12370.361 | C35: =C27*C34 -> 14349.619 | D35: =D27*D34 -> 16071.573 | E35: =E27*E34 -> 17678.73 | F35: =F27*F34 -> 19093.028 | G35: =G27*G34 -> 20238.61 | J35: =J27*J34 -> 10342.433 | K35: =K27*K34 -> 14010.549 | L35: =L27*L34 -> 18012.312 | M35: =M27*M34 -> 21694.241 | N35: =N27*N34 -> 24514.492 | O35: =O27*O34 -> 26965.941 | R35: =R27*R34 -> 10291.735 | S35: =S27*S34 -> 14996.528 | T35: =T27*T34 -> 20475.259 | U35: =U27*U34 -> 25760.435 | V35: =V27*V34 -> 30139.709 | W35: =W27*W34 -> 34057.871 | Z35: =Z27*Z34 -> 11023.998 | AA35: =AA27*AA34 -> 15987.724 | AB35: =AB27*AB34 -> 22076.654 | AC35: =AC27*AC34 -> 28626.171 | AD35: =AD27*AD34 -> 34913.161 | AE35: =AE27*AE34 -> 41533.529
A36: NWC / revenue | B36: ='Control Panel'!B$47 -> 0.13 | C36: ='Control Panel'!C$47 -> 0.13 | D36: ='Control Panel'!D$47 -> 0.125 | E36: ='Control Panel'!E$47 -> 0.12 | F36: ='Control Panel'!F$47 -> 0.115 | G36: ='Control Panel'!G$47 -> 0.11 | J36: ='Control Panel'!B$46 -> 0.11 | K36: ='Control Panel'!C$46 -> 0.105 | L36: ='Control Panel'!D$46 -> 0.1 | M36: ='Control Panel'!E$46 -> 0.095 | N36: ='Control Panel'!F$46 -> 0.09 | O36: ='Control Panel'!G$46 -> 0.09 | R36: ='Control Panel'!B$48 -> 0.1 | S36: ='Control Panel'!C$48 -> 0.095 | T36: ='Control Panel'!D$48 -> 0.09 | U36: ='Control Panel'!E$48 -> 0.085 | V36: ='Control Panel'!F$48 -> 0.08 | W36: ='Control Panel'!G$48 -> 0.08 | Z36: ='Control Panel'!B$46 -> 0.11 | AA36: ='Control Panel'!C$46 -> 0.105 | AB36: ='Control Panel'!D$46 -> 0.1 | AC36: ='Control Panel'!E$46 -> 0.095 | AD36: ='Control Panel'!F$46 -> 0.09 | AE36: ='Control Panel'!G$46 -> 0.09
A37: NWC | B37: =B27*B36 -> 40203.673 | C37: =C27*C36 -> 46636.26 | D37: =D27*D36 -> 50223.665 | E37: =E27*E36 -> 53036.19 | F37: =F27*F36 -> 54892.457 | G37: =G27*G36 -> 55656.178 | J37: =J27*J36 -> 37922.254 | K37: =K27*K36 -> 45972.114 | L37: =L27*L36 -> 52977.388 | M37: =M27*M36 -> 58884.367 | N37: =N27*N36 -> 63037.265 | O37: =O27*O36 -> 69340.991 | R37: =R27*R36 -> 36756.195 | S37: =S27*S36 -> 47489.004 | T37: =T27*T36 -> 57586.666 | U37: =U27*U36 -> 66352.636 | V37: =V27*V36 -> 73065.962 | W37: =W27*W36 -> 82564.537 | Z37: =Z27*Z36 -> 40421.326 | AA37: =AA27*AA36 -> 52459.718 | AB37: =AB27*AB36 -> 64931.335 | AC37: =AC27*AC36 -> 77699.606 | AD37: =AD27*AD36 -> 89776.699 | AE37: =AE27*AE36 -> 106800.5
A38: Change in NWC | B38: =B37-'Historical Financials'!$D$18 -> 12664.673 | C38: =C37-B37 -> 6432.5876 | D38: =D37-C37 -> 3587.4046 | E38: =E37-D37 -> 2812.5252 | F38: =F37-E37 -> 1856.2667 | G38: =G37-F37 -> 763.72114 | J38: =J37-'Historical Financials'!$D$18 -> 10383.254 | K38: =K37-J37 -> 8049.8602 | L38: =L37-K37 -> 7005.2745 | M38: =M37-L37 -> 5906.9788 | N38: =N37-M37 -> 4152.8975 | O38: =O37-N37 -> 6303.7265 | R38: =R37-'Historical Financials'!$D$18 -> 9217.195 | S38: =S37-R37 -> 10732.809 | T38: =T37-S37 -> 10097.662 | U38: =U37-T37 -> 8765.9702 | V38: =V37-U37 -> 6713.3255 | W38: =W37-V37 -> 9498.575 | Z38: =Z37-'Historical Financials'!$D$18 -> 12882.326 | AA38: =AA37-Z37 -> 12038.392 | AB38: =AB37-AA37 -> 12471.617 | AC38: =AC37-AB37 -> 12768.271 | AD38: =AD37-AC37 -> 12077.093 | AE38: =AE37-AD37 -> 17023.804
A39: FCFF | B39: =B31+B33-B35-B38 -> 124151.52 | C39: =C31+C33-C35-C38 -> 147108.33 | D39: =D31+D33-D35-D38 -> 162592.66 | E39: =E31+E33-E35-E38 -> 173621.2 | F39: =F31+F33-F35-F38 -> 181341.34 | G39: =G31+G33-G35-G38 -> 189276.83 | J39: =J31+J33-J35-J38 -> 164714.13 | K39: =K31+K33-K35-K38 -> 210689.84 | L39: =L31+L33-L35-L38 -> 248875.51 | M39: =M31+M33-M35-M38 -> 283804.11 | N39: =N31+N33-N35-N38 -> 312294.17 | O39: =O31+O33-O35-O38 -> 328998.49 | R39: =R31+R33-R35-R38 -> 189780.84 | S39: =S31+S33-S35-S38 -> 259904.53 | T39: =T31+T33-T35-T38 -> 325568.61 | U39: =U31+U33-U35-U38 -> 388413.1 | V39: =V31+V33-V35-V38 -> 443555.66 | W39: =W31+W33-W35-W38 -> 490636.11 | Z39: =Z31+Z33-Z35-Z38 -> 173753.96 | AA39: =AA31+AA33-AA35-AA38 -> 237569.94 | AB39: =AB31+AB33-AB35-AB38 -> 301146.73 | AC39: =AC31+AC33-AC35-AC38 -> 369513.79 | AD39: =AD31+AD33-AD35-AD38 -> 438601.94 | AE39: =AE31+AE33-AE35-AE38 -> 499415.96
A40: Discount period | B40: 0.5 | C40: 1.5 | D40: 2.5 | E40: 3.5 | F40: 4.5 | G40: 5.5 | J40: 0.5 | K40: 1.5 | L40: 2.5 | M40: 3.5 | N40: 4.5 | O40: 5.5 | R40: 0.5 | S40: 1.5 | T40: 2.5 | U40: 3.5 | V40: 4.5 | W40: 5.5 | Z40: 0.5 | AA40: 1.5 | AB40: 2.5 | AC40: 3.5 | AD40: 4.5 | AE40: 5.5
A41: PV of FCFF | B41: =B39/(1+B$43)^B40 -> 117241.36 | C41: =C39/(1+B$43)^C40 -> 123886.43 | D41: =D39/(1+B$43)^D40 -> 122108.26 | E41: =E39/(1+B$43)^E40 -> 116279.87 | F41: =F39/(1+B$43)^F40 -> 108306.93 | G41: =G39/(1+B$43)^G40 -> 100812.53 | J41: =J39/(1+J$43)^J40 -> 156597.21 | K41: =K39/(1+J$43)^K40 -> 181051.87 | L41: =L39/(1+J$43)^L40 -> 193307.13 | M41: =M39/(1+J$43)^M40 -> 199246.48 | N41: =N39/(1+J$43)^N40 -> 198171.93 | O41: =O39/(1+J$43)^O40 -> 188702.85 | R41: =R39/(1+R$43)^R40 -> 181043.35 | S41: =S39/(1+R$43)^S40 -> 225633.95 | T41: =T39/(1+R$43)^T40 -> 257213.37 | U41: =U39/(1+R$43)^U40 -> 279257.78 | V41: =V39/(1+R$43)^V40 -> 290215.05 | W41: =W39/(1+R$43)^W40 -> 292140.46 | Z41: =Z39/(1+Z$43)^Z40 -> 165191.56 | AA41: =AA39/(1+Z$43)^AA40 -> 204150.72 | AB41: =AB39/(1+Z$43)^AB40 -> 233907.34 | AC41: =AC39/(1+Z$43)^AC40 -> 259419.51 | AD41: =AD39/(1+Z$43)^AD40 -> 278322.82 | AE41: =AE39/(1+Z$43)^AE40 -> 286448.78
A43: WACC | B43: ='Control Panel'!$B$77+0.015 -> 0.121353 | J43: ='Control Panel'!$B$77+0 -> 0.106353 | R43: ='Control Panel'!$B$77+-0.0075 -> 0.098853 | Z43: ='Control Panel'!$B$77+0 -> 0.106353
A44: Terminal growth | B44: 0.025 | J44: 0.03 | R44: 0.035 | Z44: 0.03
A45: Terminal FCFF | B45: =G39*(1+B44) -> 194008.75 | J45: =O39*(1+J44) -> 338868.44 | R45: =W39*(1+R44) -> 507808.37 | Z45: =AE39*(1+Z44) -> 514398.44
A46: Terminal value | B46: =B45/(B43-B44) -> 2013520.6 | J46: =J45/(J43-J44) -> 4438181.1 | R46: =R45/(R43-R44) -> 7952772.3 | Z46: =Z45/(Z43-Z44) -> 6737108.5
A47: PV of terminal value | B47: =B46/(1+B43)^6 -> 1012749.4 | J47: =J46/(1+J43)^6 -> 2420152.4 | R47: =R46/(1+R43)^6 -> 4517321.1 | Z47: =Z46/(1+Z43)^6 -> 3673763.8
...

Sheet Cover
A1: DCF Banker Formula Workbook Template
A3: Workbook purpose
A4: Artifact mode | B4: banker_formula_workbook
A5: Generated timestamp | B5: 2026-05-12T00:00:00+00:00
A6: Model status | B6: Template; not decision-ready until populated with source-backed company data
A7: Primary use | B7: Live Excel DCF workbook with formulas, sensitivities, checks, and source notes
A8: No macros | B8: Yes
A9: External links | B9: None expected; builder and tests validate this
A12: Navigation
A13: Executive Summary | B13: =HYPERLINK("#'Executive Summary'!A1","Open Executive Summary") -> Open Executive Summary
A14: Control Panel | B14: =HYPERLINK("#'Control Panel'!A1","Open Control Panel") -> Open Control Panel
A15: Historical Financials | B15: =HYPERLINK("#'Historical Financials'!A1","Open Historical Financials") -> Open Historical Financials
A16: Revenue Build | B16: =HYPERLINK("#'Revenue Build'!A1","Open Revenue Build") -> Open Revenue Build
A17: Margin Cost Build | B17: =HYPERLINK("#'Margin Cost Build'!A1","Open Margin Cost Build") -> Open Margin Cost Build
A18: Working Capital | B18: =HYPERLINK("#'Working Capital'!A1","Open Working Capital") -> Open Working Capital
A19: Capex D&A | B19: =HYPERLINK("#'Capex D&A'!A1","Open Capex D&A") -> Open Capex D&A
A20: Tax Schedule | B20: =HYPERLINK("#'Tax Schedule'!A1","Open Tax Schedule") -> Open Tax Schedule
A21: Unlevered FCF | B21: =HYPERLINK("#'Unlevered FCF'!A1","Open Unlevered FCF") -> Open Unlevered FCF
A22: WACC | B22: =HYPERLINK("#'WACC'!A1","Open WACC") -> Open WACC
A23: Terminal Value | B23: =HYPERLINK("#'Terminal Value'!A1","Open Terminal Value") -> Open Terminal Value
A24: DCF Valuation | B24: =HYPERLINK("#'DCF Valuation'!A1","Open DCF Valuation") -> Open DCF Valuation
A25: Sensitivities | B25: =HYPERLINK("#'Sensitivities'!A1","Open Sensitivities") -> Open Sensitivities
A26: Checks | B26: =HYPERLINK("#'Checks'!A1","Open Checks") -> Open Checks
A27: Source Notes | B27: =HYPERLINK("#'Source Notes'!A1","Open Source Notes") -> Open Source Notes
A31: Usage notes
A32: Note 1 | B32: Populate Control Panel blue input cells first.
A33: Note 2 | B33: Replace illustrative historicals and Source Notes with source-backed company data.
A34: Note 3 | B34: Use Base/Downside/Upside scenario selection to flow assumptions through the model.
A35: Note 4 | B35: Review Checks before using the workbook in an investment memo or committee process.

Sheet Executive Summary
A1: Executive Summary
A3: Posture warning
A4: Company name | B4: ='Control Panel'!$B$4 -> NVIDIA Corporation (NVDA)
A5: Valuation date | B5: ='Control Panel'!$B$7 -> 2026-08-04
A6: Currency / units | B6: ='Control Panel'!$B$5&" / "&'Control Panel'!$B$6 -> USD / $mm except per-share data
A7: Enterprise value | B7: ='DCF Valuation'!$B$6 -> 3537229.9
A8: Equity value | B8: ='DCF Valuation'!$B$16 -> 3605453.9
A9: Implied share price | B9: ='DCF Valuation'!$B$18 -> 147.81903
A10: Current share price | B10: ='DCF Valuation'!$B$19 -> 211.94
A11: Upside / downside | B11: ='DCF Valuation'!$B$20 -> -0.30254305
A12: Base case implied valuation | B12: =Sensitivities!G$51 -> 147.81903
A13: Downside case valuation | B13: =Sensitivities!G$50 -> 109.38608
A14: Upside case valuation | B14: =Sensitivities!G$52 -> 178.86102
A15: Recommendation placeholder | B15: ='Control Panel'!$B$13 -> Screen-grade only; placeholder assumptions used.
A18: Key value drivers
A19: Forecast revenue CAGR | B19: =(('Revenue Build'!J$14/'Revenue Build'!D$14)^(1/6))-1 -> 0.20355008
A20: Terminal EBITDA margin | B20: ='Margin Cost Build'!J$11 -> 0.562
A21: Selected WACC | B21: ='Control Panel'!$B$78 -> 0.106353
A22: Terminal growth rate | B22: ='Control Panel'!$B$83 -> 0.03
A23: Terminal value % of EV | B23: ='DCF Valuation'!$B$7 -> 0.68419427
A26: Main risks and open diligence
A27: Risk 1 | B27: Replace placeholder historicals with sourced financial statements.
A28: Risk 2 | B28: Confirm WACC market inputs as of valuation date.
A29: Risk 3 | B29: Validate terminal growth, exit multiple, and terminal ROIC support.
A30: Risk 4 | B30: Review NOLs, SBC, leases, pensions, minorities, and debt-like items where material.

Sheet Control Panel
A1: Control Panel
A3: Model identity and switches
A4: Company name | B4: NVIDIA Corporation (NVDA)
A5: Currency | B5: USD
A6: Units | B6: $mm except per-share data
A7: Valuation date | B7: 2026-08-04
A8: Model status | B8: screen-grade
A9: Workbook mode | B9: banker_formula_workbook
A10: Scenario selection | B10: Base
A11: Mid-year convention | B11: Yes
A12: Current share price | B12: 211.94
A13: Recommendation placeholder | B13: Screen-grade only; placeholder assumptions used.
A14: Selected terminal value method | B14: Gordon Growth
A15: Other revenue growth factor | B15: 0
A16: Gross profit bridge / revenue | B16: 0.345
A17: Scenario assumptions
A18: Case / metric | B18: 2027E | C18: 2028E | D18: 2029E | E18: 2030E | F18: 2031E | G18: 2032E
A20: Revenue growth assumptions
A21: Base | B21: 0.36 | C21: 0.27 | D21: 0.21 | E21: 0.17 | F21: 0.13 | G21: 0.1
A22: Downside | B22: 0.22 | C22: 0.16 | D22: 0.12 | E22: 0.1 | F22: 0.08 | G22: 0.06
A23: Upside | B23: 0.45 | C23: 0.36 | D23: 0.28 | E23: 0.22 | F23: 0.17 | G23: 0.13
A25: EBITDA margin assumptions
A26: Base | B26: 0.645 | C26: 0.637 | D26: 0.619 | E26: 0.601 | F26: 0.582 | G26: 0.562
A27: Downside | B27: 0.585 | C27: 0.567 | D27: 0.549 | E27: 0.531 | F27: 0.512 | G27: 0.502
A28: Upside | B28: 0.675 | C28: 0.677 | D28: 0.659 | E28: 0.641 | F28: 0.622 | G28: 0.612
A30: EBIT margin reference assumptions
A31: Base | B31: 0.63 | C31: 0.62 | D31: 0.6 | E31: 0.58 | F31: 0.56 | G31: 0.54
A32: Downside | B32: 0.57 | C32: 0.55 | D32: 0.53 | E32: 0.51 | F32: 0.49 | G32: 0.48
A33: Upside | B33: 0.66 | C33: 0.66 | D33: 0.64 | E33: 0.62 | F33: 0.6 | G33: 0.59
A35: D&A % revenue assumptions
A36: Base | B36: 0.015 | C36: 0.017 | D36: 0.019 | E36: 0.021 | F36: 0.022 | G36: 0.022
A37: Downside | B37: 0.015 | C37: 0.017 | D37: 0.019 | E37: 0.021 | F37: 0.022 | G37: 0.022
A38: Upside | B38: 0.015 | C38: 0.017 | D38: 0.019 | E38: 0.021 | F38: 0.022 | G38: 0.022
A40: Capex % revenue assumptions
A41: Base | B41: 0.03 | C41: 0.032 | D41: 0.034 | E41: 0.035 | F41: 0.035 | G41: 0.035
A42: Downside | B42: 0.04 | C42: 0.04 | D42: 0.04 | E42: 0.04 | F42: 0.04 | G42: 0.04
A43: Upside | B43: 0.028 | C43: 0.03 | D43: 0.032 | E43: 0.033 | F43: 0.033 | G43: 0.033
A45: Operating NWC % revenue assumptions
A46: Base | B46: 0.11 | C46: 0.105 | D46: 0.1 | E46: 0.095 | F46: 0.09 | G46: 0.09
A47: Downside | B47: 0.13 | C47: 0.13 | D47: 0.125 | E47: 0.12 | F47: 0.115 | G47: 0.11
...

Sheet Historical Financials
A1: Historical Financials
A5: Fiscal year | B5: 2022A | C5: 2023A | D5: 2026A | E5: 2025E | F5: 2026E | G5: 2027E | H5: 2028E | I5: 2029E | J5: 2030E | K5: Source label | L5: Notes
A6: Revenue | B6: 1000 | C6: 1120 | D6: 253491 | E6: ='Revenue Build'!E$14 -> 344747.76 | F6: ='Revenue Build'!F$14 -> 437829.66 | G6: ='Revenue Build'!G$14 -> 529773.88 | H6: ='Revenue Build'!H$14 -> 619835.44 | I6: ='Revenue Build'!I$14 -> 700414.05 | J6: ='Revenue Build'!J$14 -> 770455.46 | K6: reported | L6: Latest historical year populated from plan.json; add multi-year sourced history before circulation.
A7: Revenue growth | B7: - | C7: =C6/B6-1 -> 0.12 | D7: =D6/C6-1 -> 225.33125 | E7: =E6/D6-1 -> 0.36 | F7: =F6/E6-1 -> 0.27 | G7: =G6/F6-1 -> 0.21 | H7: =H6/G6-1 -> 0.17 | I7: =I6/H6-1 -> 0.13 | J7: =J6/I6-1 -> 0.1 | K7: derived | L7: Formula-derived
A8: Gross profit | B8: 560 | C8: 638.4 | D8: 719.2 | E8: ='Margin Cost Build'!E$9 -> 341300.28 | F8: ='Margin Cost Build'!F$9 -> 429948.72 | G8: ='Margin Cost Build'!G$9 -> 510702.02 | H8: ='Margin Cost Build'!H$9 -> 586364.33 | I8: ='Margin Cost Build'!I$9 -> 649283.82 | J8: ='Margin Cost Build'!J$9 -> 698803.1 | K8: reported | L8: Latest historical year populated from plan.json; add multi-year sourced history before circulation.
A9: Gross margin | B9: =B8/B6 -> 0.56 | C9: =C8/C6 -> 0.57 | D9: =D8/D6 -> 0.0028371816 | E9: =E8/E6 -> 0.99 | F9: =F8/F6 -> 0.982 | G9: =G8/G6 -> 0.964 | H9: =H8/H6 -> 0.946 | I9: =I8/I6 -> 0.927 | J9: =J8/J6 -> 0.907 | K9: derived | L9: Formula-derived
A10: EBITDA | B10: 210 | C10: 252 | D10: 165514 | E10: ='Margin Cost Build'!E$12 -> 222362.31 | F10: ='Margin Cost Build'!F$12 -> 278897.49 | G10: ='Margin Cost Build'!G$12 -> 327930.03 | H10: ='Margin Cost Build'!H$12 -> 372521.1 | I10: ='Margin Cost Build'!I$12 -> 407640.98 | J10: ='Margin Cost Build'!J$12 -> 432995.97 | K10: reported | L10: Latest historical year populated from plan.json; add multi-year sourced history before circulation.
A11: EBITDA margin | B11: =B10/B6 -> 0.21 | C11: =C10/C6 -> 0.225 | D11: =D10/D6 -> 0.65293837 | E11: =E10/E6 -> 0.645 | F11: =F10/F6 -> 0.637 | G11: =G10/G6 -> 0.619 | H11: =H10/H6 -> 0.601 | I11: =I10/I6 -> 0.582 | J11: =J10/J6 -> 0.562 | K11: derived | L11: Formula-derived
A12: D&A | B12: 55 | C12: 61.6 | D12: 3229 | E12: ='Capex D&A'!E$12 -> 5171.2164 | F12: ='Capex D&A'!F$12 -> 7443.1041 | G12: ='Capex D&A'!G$12 -> 10065.704 | H12: ='Capex D&A'!H$12 -> 13016.544 | I12: ='Capex D&A'!I$12 -> 15409.109 | J12: ='Capex D&A'!J$12 -> 16950.02 | K12: reported | L12: Latest historical year populated from plan.json; add multi-year sourced history before circulation.
A13: EBIT | B13: 155 | C13: 190.4 | D13: 162285 | E13: ='Margin Cost Build'!E$15 -> 217191.09 | F13: ='Margin Cost Build'!F$15 -> 271454.39 | G13: ='Margin Cost Build'!G$15 -> 317864.33 | H13: ='Margin Cost Build'!H$15 -> 359504.56 | I13: ='Margin Cost Build'!I$15 -> 392231.87 | J13: ='Margin Cost Build'!J$15 -> 416045.95 | K13: reported | L13: Latest historical year populated from plan.json; add multi-year sourced history before circulation.
A14: EBIT margin | B14: =B13/B6 -> 0.155 | C14: =C13/C6 -> 0.17 | D14: =D13/D6 -> 0.64020024 | E14: =E13/E6 -> 0.63 | F14: =F13/F6 -> 0.62 | G14: =G13/G6 -> 0.6 | H14: =H13/H6 -> 0.58 | I14: =I13/I6 -> 0.56 | J14: =J13/J6 -> 0.54 | K14: derived | L14: Formula-derived
A15: Taxes | B15: 34.1 | C15: 43.8 | D15: 26000 | E15: ='Tax Schedule'!E$12 -> 36922.485 | F15: ='Tax Schedule'!F$12 -> 46147.246 | G15: ='Tax Schedule'!G$12 -> 54036.936 | H15: ='Tax Schedule'!H$12 -> 61115.775 | I15: ='Tax Schedule'!I$12 -> 66679.418 | J15: ='Tax Schedule'!J$12 -> 70727.811 | K15: reported | L15: Latest historical year populated from plan.json; add multi-year sourced history before circulation.
A16: Net income | B16: 86 | C16: 112 | D16: 142 | E16: =E13-E15 -> 180268.6 | F16: =F13-F15 -> 225307.14 | G16: =G13-G15 -> 263827.39 | H16: =H13-H15 -> 298388.78 | I16: =I13-I15 -> 325552.45 | J16: =J13-J15 -> 345318.14 | K16: reported | L16: Latest historical year populated from plan.json; add multi-year sourced history before circulation.
A17: Capex | B17: 78 | C17: 82 | D17: 6572 | E17: ='Capex D&A'!E$9 -> 10342.433 | F17: ='Capex D&A'!F$9 -> 14010.549 | G17: ='Capex D&A'!G$9 -> 18012.312 | H17: ='Capex D&A'!H$9 -> 21694.241 | I17: ='Capex D&A'!I$9 -> 24514.492 | J17: ='Capex D&A'!J$9 -> 26965.941 | K17: reported | L17: Latest historical year populated from plan.json; add multi-year sourced history before circulation.
A18: Operating NWC | B18: 118 | C18: 132 | D18: 27539 | E18: ='Working Capital'!E$16 -> 37922.254 | F18: ='Working Capital'!F$16 -> 45972.114 | G18: ='Working Capital'!G$16 -> 52977.388 | H18: ='Working Capital'!H$16 -> 58884.367 | I18: ='Working Capital'!I$16 -> 63037.265 | J18: ='Working Capital'!J$16 -> 69340.991 | K18: reported | L18: Latest historical year populated from plan.json; add multi-year sourced history before circulation.
A19: Change in NWC | B19: - | C19: =C18/C6-B18/B6 -> -0.00014285714 | D19: =D18/D6-C18/C6 -> -0.0092181774 | E19: ='Working Capital'!E$17 -> 10383.254 | F19: ='Working Capital'!F$17 -> 8049.8602 | G19: ='Working Capital'!G$17 -> 7005.2745 | H19: ='Working Capital'!H$17 -> 5906.9788 | I19: ='Working Capital'!I$17 -> 4152.8975 | J19: ='Working Capital'!J$17 -> 6303.7265 | K19: derived | L19: Formula-derived
A20: Unlevered FCF | B20: 86 | C20: 98 | D20: 130905 | E20: ='Unlevered FCF'!E$11 -> 5171.2164 | F20: ='Unlevered FCF'!F$11 -> 7443.1041 | G20: ='Unlevered FCF'!G$11 -> 10065.704 | H20: ='Unlevered FCF'!H$11 -> 13016.544 | I20: ='Unlevered FCF'!I$11 -> 15409.109 | J20: ='Unlevered FCF'!J$11 -> 16950.02 | K20: reported | L20: Latest historical year populated from plan.json; add multi-year sourced history before circulation.
A21: PP&E | B21: 420 | C21: 440.4 | D21: 460.2 | E21: ='Capex D&A'!E$13 -> 8954.6164 | F21: ='Capex D&A'!F$13 -> 15522.061 | G21: ='Capex D&A'!G$13 -> 23468.669 | H21: ='Capex D&A'!H$13 -> 32146.366 | I21: ='Capex D&A'!I$13 -> 41251.748 | J21: ='Capex D&A'!J$13 -> 51267.669 | K21: reported | L21: Latest historical year populated from plan.json; add multi-year sourced history before circulation.

Sheet Revenue Build
A1: Revenue Build
A5: Fiscal year | B5: 2022A | C5: 2023A | D5: 2024A | E5: 2025E | F5: 2026E | G5: 2027E | H5: 2028E | I5: 2029E | J5: 2030E
A7: Scenario-linked revenue forecast
A8: Selected scenario | B8: Actual | C8: Actual | D8: Actual | E8: ='Control Panel'!$B$10 -> Base | F8: ='Control Panel'!$B$10 -> Base | G8: ='Control Panel'!$B$10 -> Base | H8: ='Control Panel'!$B$10 -> Base | I8: ='Control Panel'!$B$10 -> Base | J8: ='Control Panel'!$B$10 -> Base
A9: Revenue growth assumption | B9: - | C9: =C14/B14-1 -> 0.12 | D9: =D14/C14-1 -> 225.33125 | E9: =INDEX('Control Panel'!B$21:B$23,MATCH('Control Panel'!$B$10,'Control Panel'!$A$21:$A$23,0)) -> 0.36 | F9: =INDEX('Control Panel'!C$21:C$23,MATCH('Control Panel'!$B$10,'Control Panel'!$A$21:$A$23,0)) -> 0.27 | G9: =INDEX('Control Panel'!D$21:D$23,MATCH('Control Panel'!$B$10,'Control Panel'!$A$21:$A$23,0)) -> 0.21 | H9: =INDEX('Control Panel'!E$21:E$23,MATCH('Control Panel'!$B$10,'Control Panel'!$A$21:$A$23,0)) -> 0.17 | I9: =INDEX('Control Panel'!F$21:F$23,MATCH('Control Panel'!$B$10,'Control Panel'!$A$21:$A$23,0)) -> 0.13 | J9: =INDEX('Control Panel'!G$21:G$23,MATCH('Control Panel'!$B$10,'Control Panel'!$A$21:$A$23,0)) -> 0.1
A10: Core revenue | B10: 780 | C10: 873.6 | D10: 253491 | E10: =D10*(1+E9) -> 344747.76 | F10: =E10*(1+F9) -> 437829.66 | G10: =F10*(1+G9) -> 529773.88 | H10: =G10*(1+H9) -> 619835.44 | I10: =H10*(1+I9) -> 700414.05 | J10: =I10*(1+J9) -> 770455.46
A11: Other revenue | B11: 220 | C11: 246.4 | D11: 0 | E11: =D11*(1+E9*'Control Panel'!$B$15) -> 0 | F11: =E11*(1+F9*'Control Panel'!$B$15) -> 0 | G11: =F11*(1+G9*'Control Panel'!$B$15) -> 0 | H11: =G11*(1+H9*'Control Panel'!$B$15) -> 0 | I11: =H11*(1+I9*'Control Panel'!$B$15) -> 0 | J11: =I11*(1+J9*'Control Panel'!$B$15) -> 0
A12: Segment mix / driver placeholder | B12: =B10/B14 -> 0.78 | C12: =C10/C14 -> 0.78 | D12: =D10/D14 -> 1 | E12: =E10/E14 -> 1 | F12: =F10/F14 -> 1 | G12: =G10/G14 -> 1 | H12: =H10/H14 -> 1 | I12: =I10/I14 -> 1 | J12: =J10/J14 -> 1
A14: Output revenue | B14: =SUM(B10:B11) -> 1000 | C14: =SUM(C10:C11) -> 1120 | D14: =SUM(D10:D11) -> 253491 | E14: =SUM(E10:E11) -> 344747.76 | F14: =SUM(F10:F11) -> 437829.66 | G14: =SUM(G10:G11) -> 529773.88 | H14: =SUM(H10:H11) -> 619835.44 | I14: =SUM(I10:I11) -> 700414.05 | J14: =SUM(J10:J11) -> 770455.46
A15: Output revenue growth | B15: - | C15: =C14/B14-1 -> 0.12 | D15: =D14/C14-1 -> 225.33125 | E15: =E14/D14-1 -> 0.36 | F15: =F14/E14-1 -> 0.27 | G15: =G14/F14-1 -> 0.21 | H15: =H14/G14-1 -> 0.17 | I15: =I14/H14-1 -> 0.13 | J15: =J14/I14-1 -> 0.1

Sheet Margin Cost Build
A1: Margin / Cost Build
A5: Fiscal year | B5: 2022A | C5: 2023A | D5: 2024A | E5: 2025E | F5: 2026E | G5: 2027E | H5: 2028E | I5: 2029E | J5: 2030E
A7: Operating profitability
A8: Revenue | B8: ='Historical Financials'!B$6 -> 1000 | C8: ='Historical Financials'!C$6 -> 1120 | D8: ='Historical Financials'!D$6 -> 253491 | E8: ='Revenue Build'!E$14 -> 344747.76 | F8: ='Revenue Build'!F$14 -> 437829.66 | G8: ='Revenue Build'!G$14 -> 529773.88 | H8: ='Revenue Build'!H$14 -> 619835.44 | I8: ='Revenue Build'!I$14 -> 700414.05 | J8: ='Revenue Build'!J$14 -> 770455.46
A9: Gross profit | B9: ='Historical Financials'!B$8 -> 560 | C9: ='Historical Financials'!C$8 -> 638.4 | D9: ='Historical Financials'!D$8 -> 719.2 | E9: =E12+(E8*'Control Panel'!$B$16) -> 341300.28 | F9: =F12+(F8*'Control Panel'!$B$16) -> 429948.72 | G9: =G12+(G8*'Control Panel'!$B$16) -> 510702.02 | H9: =H12+(H8*'Control Panel'!$B$16) -> 586364.33 | I9: =I12+(I8*'Control Panel'!$B$16) -> 649283.82 | J9: =J12+(J8*'Control Panel'!$B$16) -> 698803.1
A10: Gross margin | B10: =B9/B8 -> 0.56 | C10: =C9/C8 -> 0.57 | D10: =D9/D8 -> 0.0028371816 | E10: =E9/E8 -> 0.99 | F10: =F9/F8 -> 0.982 | G10: =G9/G8 -> 0.964 | H10: =H9/H8 -> 0.946 | I10: =I9/I8 -> 0.927 | J10: =J9/J8 -> 0.907
A11: EBITDA margin assumption | B11: ='Historical Financials'!B$11 -> 0.21 | C11: ='Historical Financials'!C$11 -> 0.225 | D11: ='Historical Financials'!D$11 -> 0.65293837 | E11: =INDEX('Control Panel'!B$26:B$28,MATCH('Control Panel'!$B$10,'Control Panel'!$A$26:$A$28,0)) -> 0.645 | F11: =INDEX('Control Panel'!C$26:C$28,MATCH('Control Panel'!$B$10,'Control Panel'!$A$26:$A$28,0)) -> 0.637 | G11: =INDEX('Control Panel'!D$26:D$28,MATCH('Control Panel'!$B$10,'Control Panel'!$A$26:$A$28,0)) -> 0.619 | H11: =INDEX('Control Panel'!E$26:E$28,MATCH('Control Panel'!$B$10,'Control Panel'!$A$26:$A$28,0)) -> 0.601 | I11: =INDEX('Control Panel'!F$26:F$28,MATCH('Control Panel'!$B$10,'Control Panel'!$A$26:$A$28,0)) -> 0.582 | J11: =INDEX('Control Panel'!G$26:G$28,MATCH('Control Panel'!$B$10,'Control Panel'!$A$26:$A$28,0)) -> 0.562
A12: EBITDA | B12: ='Historical Financials'!B$10 -> 210 | C12: ='Historical Financials'!C$10 -> 252 | D12: ='Historical Financials'!D$10 -> 165514 | E12: =E8*E11 -> 222362.31 | F12: =F8*F11 -> 278897.49 | G12: =G8*G11 -> 327930.03 | H12: =H8*H11 -> 372521.1 | I12: =I8*I11 -> 407640.98 | J12: =J8*J11 -> 432995.97
A13: D&A | B13: ='Historical Financials'!B$12 -> 55 | C13: ='Historical Financials'!C$12 -> 61.6 | D13: ='Historical Financials'!D$12 -> 3229 | E13: ='Capex D&A'!E$12 -> 5171.2164 | F13: ='Capex D&A'!F$12 -> 7443.1041 | G13: ='Capex D&A'!G$12 -> 10065.704 | H13: ='Capex D&A'!H$12 -> 13016.544 | I13: ='Capex D&A'!I$12 -> 15409.109 | J13: ='Capex D&A'!J$12 -> 16950.02
A14: D&A % revenue | B14: =B13/B8 -> 0.055 | C14: =C13/C8 -> 0.055 | D14: =D13/D8 -> 0.012738125 | E14: =E13/E8 -> 0.015 | F14: =F13/F8 -> 0.017 | G14: =G13/G8 -> 0.019 | H14: =H13/H8 -> 0.021 | I14: =I13/I8 -> 0.022 | J14: =J13/J8 -> 0.022
A15: EBIT | B15: =B12-B13 -> 155 | C15: =C12-C13 -> 190.4 | D15: =D12-D13 -> 162285 | E15: =E12-E13 -> 217191.09 | F15: =F12-F13 -> 271454.39 | G15: =G12-G13 -> 317864.33 | H15: =H12-H13 -> 359504.56 | I15: =I12-I13 -> 392231.87 | J15: =J12-J13 -> 416045.95
A16: EBIT margin | B16: =B15/B8 -> 0.155 | C16: =C15/C8 -> 0.17 | D16: =D15/D8 -> 0.64020024 | E16: =E15/E8 -> 0.63 | F16: =F15/F8 -> 0.62 | G16: =G15/G8 -> 0.6 | H16: =H15/H8 -> 0.58 | I16: =I15/I8 -> 0.56 | J16: =J15/J8 -> 0.54
A17: Margin expansion / compression vs prior year | B17: - | C17: =C16-B16 -> 0.015 | D17: =D16-C16 -> 0.47020024 | E17: =E16-D16 -> -0.010200244 | F17: =F16-E16 -> -0.01 | G17: =G16-F16 -> -0.02 | H17: =H16-G16 -> -0.02 | I17: =I16-H16 -> -0.02 | J17: =J16-I16 -> -0.02
A18: Cash taxes | B18: ='Historical Financials'!B$15 -> 34.1 | C18: ='Historical Financials'!C$15 -> 43.8 | D18: ='Historical Financials'!D$15 -> 26000 | E18: ='Tax Schedule'!E$12 -> 36922.485 | F18: ='Tax Schedule'!F$12 -> 46147.246 | G18: ='Tax Schedule'!G$12 -> 54036.936 | H18: ='Tax Schedule'!H$12 -> 61115.775 | I18: ='Tax Schedule'!I$12 -> 66679.418 | J18: ='Tax Schedule'!J$12 -> 70727.811

Sheet Working Capital
A1: Working Capital
A5: Fiscal year | B5: 2022A | C5: 2023A | D5: 2024A | E5: 2025E | F5: 2026E | G5: 2027E | H5: 2028E | I5: 2029E | J5: 2030E
A7: Operating working capital
A8: Revenue | B8: ='Historical Financials'!B$6 -> 1000 | C8: ='Historical Financials'!C$6 -> 1120 | D8: ='Historical Financials'!D$6 -> 253491 | E8: ='Revenue Build'!E$14 -> 344747.76 | F8: ='Revenue Build'!F$14 -> 437829.66 | G8: ='Revenue Build'!G$14 -> 529773.88 | H8: ='Revenue Build'!H$14 -> 619835.44 | I8: ='Revenue Build'!I$14 -> 700414.05 | J8: ='Revenue Build'!J$14 -> 770455.46
A9: AR % revenue | B9: =B10/B8 -> 0.14 | C9: =C10/C8 -> 0.14 | D9: =D10/D8 -> 0.14 | E9: ='Control Panel'!B$61 -> 0.11 | F9: ='Control Panel'!C$61 -> 0.105 | G9: ='Control Panel'!D$61 -> 0.1 | H9: ='Control Panel'!E$61 -> 0.095 | I9: ='Control Panel'!F$61 -> 0.09 | J9: ='Control Panel'!G$61 -> 0.09
A10: Accounts receivable | B10: =B8*0.14 -> 140 | C10: =C8*0.14 -> 156.8 | D10: =D8*0.14 -> 35488.74 | E10: =E8*E9 -> 37922.254 | F10: =F8*F9 -> 45972.114 | G10: =G8*G9 -> 52977.388 | H10: =H8*H9 -> 58884.367 | I10: =I8*I9 -> 63037.265 | J10: =J8*J9 -> 69340.991
A11: Inventory % revenue | B11: =B12/B8 -> 0.06 | C11: =C12/C8 -> 0.06 | D11: =D12/D8 -> 0.06 | E11: ='Control Panel'!B$62 -> 0 | F11: ='Control Panel'!C$62 -> 0 | G11: ='Control Panel'!D$62 -> 0 | H11: ='Control Panel'!E$62 -> 0 | I11: ='Control Panel'!F$62 -> 0 | J11: ='Control Panel'!G$62 -> 0
A12: Inventory | B12: =B8*0.06 -> 60 | C12: =C8*0.06 -> 67.2 | D12: =D8*0.06 -> 15209.46 | E12: =E8*E11 -> 0 | F12: =F8*F11 -> 0 | G12: =G8*G11 -> 0 | H12: =H8*H11 -> 0 | I12: =I8*I11 -> 0 | J12: =J8*J11 -> 0
A13: AP % revenue | B13: =B14/B8 -> 0.085 | C13: =C14/C8 -> 0.085 | D13: =D14/D8 -> 0.085 | E13: ='Control Panel'!B$63 -> 0 | F13: ='Control Panel'!C$63 -> 0 | G13: ='Control Panel'!D$63 -> 0 | H13: ='Control Panel'!E$63 -> 0 | I13: ='Control Panel'!F$63 -> 0 | J13: ='Control Panel'!G$63 -> 0
A14: Accounts payable | B14: =B8*0.085 -> 85 | C14: =C8*0.085 -> 95.2 | D14: =D8*0.085 -> 21546.735 | E14: =E8*E13 -> 0 | F14: =F8*F13 -> 0 | G14: =G8*G13 -> 0 | H14: =H8*H13 -> 0 | I14: =I8*I13 -> 0 | J14: =J8*J13 -> 0
A15: Other current assets / liabilities net | B15: =B8*0 -> 0 | C15: =C8*0 -> 0 | D15: =D8*0 -> 0 | E15: =E8*('Control Panel'!B$64-'Control Panel'!B$65) -> 0 | F15: =F8*('Control Panel'!C$64-'Control Panel'!C$65) -> 0 | G15: =G8*('Control Panel'!D$64-'Control Panel'!D$65) -> 0 | H15: =H8*('Control Panel'!E$64-'Control Panel'!E$65) -> 0 | I15: =I8*('Control Panel'!F$64-'Control Panel'!F$65) -> 0 | J15: =J8*('Control Panel'!G$64-'Control Panel'!G$65) -> 0
A16: Operating NWC | B16: ='Historical Financials'!B$18 -> 118 | C16: ='Historical Financials'!C$18 -> 132 | D16: ='Historical Financials'!D$18 -> 27539 | E16: =E10+E12-E14+E15 -> 37922.254 | F16: =F10+F12-F14+F15 -> 45972.114 | G16: =G10+G12-G14+G15 -> 52977.388 | H16: =H10+H12-H14+H15 -> 58884.367 | I16: =I10+I12-I14+I15 -> 63037.265 | J16: =J10+J12-J14+J15 -> 69340.991
A17: Change in NWC | B17: 0 | C17: =C16-B16 -> 14 | D17: =D16-C16 -> 27407 | E17: =E16-D16 -> 10383.254 | F17: =F16-E16 -> 8049.8602 | G17: =G16-F16 -> 7005.2745 | H17: =H16-G16 -> 5906.9788 | I17: =I16-H16 -> 4152.8975 | J17: =J16-I16 -> 6303.7265
A18: NWC % revenue | B18: =B16/B8 -> 0.118 | C18: =C16/C8 -> 0.11785714 | D18: =D16/D8 -> 0.10863897 | E18: =E16/E8 -> 0.11 | F18: =F16/F8 -> 0.105 | G18: =G16/G8 -> 0.1 | H18: =H16/H8 -> 0.095 | I18: =I16/I8 -> 0.09 | J18: =J16/J8 -> 0.09
A19: Cash flow impact of NWC | B19: =-B17 -> 0 | C19: =-C17 -> -14 | D19: =-D17 -> -27407 | E19: =-E17 -> -10383.254 | F19: =-F17 -> -8049.8602 | G19: =-G17 -> -7005.2745 | H19: =-H17 -> -5906.9788 | I19: =-I17 -> -4152.8975 | J19: =-J17 -> -6303.7265

Sheet Capex D&A
A1: Capex and D&A
A5: Fiscal year | B5: 2022A | C5: 2023A | D5: 2024A | E5: 2025E | F5: 2026E | G5: 2027E | H5: 2028E | I5: 2029E | J5: 2030E
A7: Capital expenditure and depreciation schedule
A8: Revenue | B8: ='Historical Financials'!B$6 -> 1000 | C8: ='Historical Financials'!C$6 -> 1120 | D8: ='Historical Financials'!D$6 -> 253491 | E8: ='Revenue Build'!E$14 -> 344747.76 | F8: ='Revenue Build'!F$14 -> 437829.66 | G8: ='Revenue Build'!G$14 -> 529773.88 | H8: ='Revenue Build'!H$14 -> 619835.44 | I8: ='Revenue Build'!I$14 -> 700414.05 | J8: ='Revenue Build'!J$14 -> 770455.46
A9: Capex | B9: ='Historical Financials'!B$17 -> 78 | C9: ='Historical Financials'!C$17 -> 82 | D9: ='Historical Financials'!D$17 -> 6572 | E9: =E8*E10 -> 10342.433 | F9: =F8*F10 -> 14010.549 | G9: =G8*G10 -> 18012.312 | H9: =H8*H10 -> 21694.241 | I9: =I8*I10 -> 24514.492 | J9: =J8*J10 -> 26965.941
A10: Capex % revenue | B10: =B9/B8 -> 0.078 | C10: =C9/C8 -> 0.073214286 | D10: =D9/D8 -> 0.02592597 | E10: =INDEX('Control Panel'!B$41:B$43,MATCH('Control Panel'!$B$10,'Control Panel'!$A$41:$A$43,0)) -> 0.03 | F10: =INDEX('Control Panel'!C$41:C$43,MATCH('Control Panel'!$B$10,'Control Panel'!$A$41:$A$43,0)) -> 0.032 | G10: =INDEX('Control Panel'!D$41:D$43,MATCH('Control Panel'!$B$10,'Control Panel'!$A$41:$A$43,0)) -> 0.034 | H10: =INDEX('Control Panel'!E$41:E$43,MATCH('Control Panel'!$B$10,'Control Panel'!$A$41:$A$43,0)) -> 0.035 | I10: =INDEX('Control Panel'!F$41:F$43,MATCH('Control Panel'!$B$10,'Control Panel'!$A$41:$A$43,0)) -> 0.035 | J10: =INDEX('Control Panel'!G$41:G$43,MATCH('Control Panel'!$B$10,'Control Panel'!$A$41:$A$43,0)) -> 0.035
A11: Beginning PP&E | B11: 397 | C11: =B13 -> 420 | D11: =C13 -> 440.4 | E11: =D13 -> 3783.4 | F11: =E13 -> 8954.6164 | G11: =F13 -> 15522.061 | H11: =G13 -> 23468.669 | I11: =H13 -> 32146.366 | J11: =I13 -> 41251.748
A12: D&A | B12: ='Historical Financials'!B$12 -> 55 | C12: ='Historical Financials'!C$12 -> 61.6 | D12: ='Historical Financials'!D$12 -> 3229 | E12: =E8*E14 -> 5171.2164 | F12: =F8*F14 -> 7443.1041 | G12: =G8*G14 -> 10065.704 | H12: =H8*H14 -> 13016.544 | I12: =I8*I14 -> 15409.109 | J12: =J8*J14 -> 16950.02
A13: Ending PP&E | B13: =B11+B9-B12 -> 420 | C13: =C11+C9-C12 -> 440.4 | D13: =D11+D9-D12 -> 3783.4 | E13: =E11+E9-E12 -> 8954.6164 | F13: =F11+F9-F12 -> 15522.061 | G13: =G11+G9-G12 -> 23468.669 | H13: =H11+H9-H12 -> 32146.366 | I13: =I11+I9-I12 -> 41251.748 | J13: =J11+J9-J12 -> 51267.669
A14: D&A % revenue | B14: =B12/B8 -> 0.055 | C14: =C12/C8 -> 0.055 | D14: =D12/D8 -> 0.012738125 | E14: =INDEX('Control Panel'!B$36:B$38,MATCH('Control Panel'!$B$10,'Control Panel'!$A$36:$A$38,0)) -> 0.015 | F14: =INDEX('Control Panel'!C$36:C$38,MATCH('Control Panel'!$B$10,'Control Panel'!$A$36:$A$38,0)) -> 0.017 | G14: =INDEX('Control Panel'!D$36:D$38,MATCH('Control Panel'!$B$10,'Control Panel'!$A$36:$A$38,0)) -> 0.019 | H14: =INDEX('Control Panel'!E$36:E$38,MATCH('Control Panel'!$B$10,'Control Panel'!$A$36:$A$38,0)) -> 0.021 | I14: =INDEX('Control Panel'!F$36:F$38,MATCH('Control Panel'!$B$10,'Control Panel'!$A$36:$A$38,0)) -> 0.022 | J14: =INDEX('Control Panel'!G$36:G$38,MATCH('Control Panel'!$B$10,'Control Panel'!$A$36:$A$38,0)) -> 0.022
A15: D&A % beginning PP&E | B15: =B12/B11 -> 0.13853904 | C15: =C12/C11 -> 0.14666667 | D15: =D12/D11 -> 7.3319709 | E15: =E12/E11 -> 1.3668173 | F15: =F12/F11 -> 0.83120301 | G15: =G12/G11 -> 0.64847726 | H15: =H12/H11 -> 0.55463495 | I15: =I12/I11 -> 0.47934218 | J15: =J12/J11 -> 0.41089216

Sheet Tax Schedule
A1: Tax Schedule
A5: Fiscal year | B5: 2022A | C5: 2023A | D5: 2024A | E5: 2025E | F5: 2026E | G5: 2027E | H5: 2028E | I5: 2029E | J5: 2030E
A7: Book and cash tax calculation
A8: EBIT | B8: ='Historical Financials'!B$13 -> 155 | C8: ='Historical Financials'!C$13 -> 190.4 | D8: ='Historical Financials'!D$13 -> 162285 | E8: ='Margin Cost Build'!E$15 -> 217191.09 | F8: ='Margin Cost Build'!F$15 -> 271454.39 | G8: ='Margin Cost Build'!G$15 -> 317864.33 | H8: ='Margin Cost Build'!H$15 -> 359504.56 | I8: ='Margin Cost Build'!I$15 -> 392231.87 | J8: ='Margin Cost Build'!J$15 -> 416045.95
A9: Statutory tax rate | B9: ='Historical Financials'!B$15/B8 -> 0.22 | C9: ='Historical Financials'!C$15/C8 -> 0.23004202 | D9: ='Historical Financials'!D$15/D8 -> 0.16021197 | E9: =INDEX('Control Panel'!B$51:B$53,MATCH('Control Panel'!$B$10,'Control Panel'!$A$51:$A$53,0)) -> 0.17 | F9: =INDEX('Control Panel'!C$51:C$53,MATCH('Control Panel'!$B$10,'Control Panel'!$A$51:$A$53,0)) -> 0.17 | G9: =INDEX('Control Panel'!D$51:D$53,MATCH('Control Panel'!$B$10,'Control Panel'!$A$51:$A$53,0)) -> 0.17 | H9: =INDEX('Control Panel'!E$51:E$53,MATCH('Control Panel'!$B$10,'Control Panel'!$A$51:$A$53,0)) -> 0.17 | I9: =INDEX('Control Panel'!F$51:F$53,MATCH('Control Panel'!$B$10,'Control Panel'!$A$51:$A$53,0)) -> 0.17 | J9: =INDEX('Control Panel'!G$51:G$53,MATCH('Control Panel'!$B$10,'Control Panel'!$A$51:$A$53,0)) -> 0.17
A10: Cash tax rate | B10: =B9 -> 0.22 | C10: =C9 -> 0.23004202 | D10: =D9 -> 0.16021197 | E10: =INDEX('Control Panel'!B$56:B$58,MATCH('Control Panel'!$B$10,'Control Panel'!$A$56:$A$58,0)) -> 0.17 | F10: =INDEX('Control Panel'!C$56:C$58,MATCH('Control Panel'!$B$10,'Control Panel'!$A$56:$A$58,0)) -> 0.17 | G10: =INDEX('Control Panel'!D$56:D$58,MATCH('Control Panel'!$B$10,'Control Panel'!$A$56:$A$58,0)) -> 0.17 | H10: =INDEX('Control Panel'!E$56:E$58,MATCH('Control Panel'!$B$10,'Control Panel'!$A$56:$A$58,0)) -> 0.17 | I10: =INDEX('Control Panel'!F$56:F$58,MATCH('Control Panel'!$B$10,'Control Panel'!$A$56:$A$58,0)) -> 0.17 | J10: =INDEX('Control Panel'!G$56:G$58,MATCH('Control Panel'!$B$10,'Control Panel'!$A$56:$A$58,0)) -> 0.17
A11: NOL usage placeholder | B11: 0 | C11: 0 | D11: 0 | E11: 0 | F11: 0 | G11: 0 | H11: 0 | I11: 0 | J11: 0
A12: Cash taxes | B12: ='Historical Financials'!B$15 -> 34.1 | C12: ='Historical Financials'!C$15 -> 43.8 | D12: ='Historical Financials'!D$15 -> 26000 | E12: =MAX(0,E8*E10-E11) -> 36922.485 | F12: =MAX(0,F8*F10-F11) -> 46147.246 | G12: =MAX(0,G8*G10-G11) -> 54036.936 | H12: =MAX(0,H8*H10-H11) -> 61115.775 | I12: =MAX(0,I8*I10-I11) -> 66679.418 | J12: =MAX(0,J8*J10-J11) -> 70727.811
A13: Deferred tax placeholder | B13: 0 | C13: 0 | D13: 0 | E13: =E8*E9-E12 -> 0 | F13: =F8*F9-F12 -> 0 | G13: =G8*G9-G12 -> 0 | H13: =H8*H9-H12 -> 0 | I13: =I8*I9-I12 -> 0 | J13: =J8*J9-J12 -> 0
A14: Tax warning / simplified treatment | B14: Replace placeholder NOL/deferred tax logic where material | C14: Replace placeholder NOL/deferred tax logic where material | D14: Replace placeholder NOL/deferred tax logic where material | E14: Simplified cash tax schedule; add NOL detail if material | F14: Simplified cash tax schedule; add NOL detail if material | G14: Simplified cash tax schedule; add NOL detail if material | H14: Simplified cash tax schedule; add NOL detail if material | I14: Simplified cash tax schedule; add NOL detail if material | J14: Simplified cash tax schedule; add NOL detail if material

Sheet Unlevered FCF
A1: Unlevered Free Cash Flow
A5: Fiscal year | B5: 2022A | C5: 2023A | D5: 2024A | E5: 2025E | F5: 2026E | G5: 2027E | H5: 2028E | I5: 2029E | J5: 2030E
A7: Core DCF cash flows
A8: EBIT | B8: ='Historical Financials'!B$13 -> 155 | C8: ='Historical Financials'!C$13 -> 190.4 | D8: ='Historical Financials'!D$13 -> 162285 | E8: ='Margin Cost Build'!E$15 -> 217191.09 | F8: ='Margin Cost Build'!F$15 -> 271454.39 | G8: ='Margin Cost Build'!G$15 -> 317864.33 | H8: ='Margin Cost Build'!H$15 -> 359504.56 | I8: ='Margin Cost Build'!I$15 -> 392231.87 | J8: ='Margin Cost Build'!J$15 -> 416045.95
A9: Less: cash taxes | B9: ='Historical Financials'!B$15 -> 34.1 | C9: ='Historical Financials'!C$15 -> 43.8 | D9: ='Historical Financials'!D$15 -> 26000 | E9: ='Tax Schedule'!E$12 -> 36922.485 | F9: ='Tax Schedule'!F$12 -> 46147.246 | G9: ='Tax Schedule'!G$12 -> 54036.936 | H9: ='Tax Schedule'!H$12 -> 61115.775 | I9: ='Tax Schedule'!I$12 -> 66679.418 | J9: ='Tax Schedule'!J$12 -> 70727.811
A10: NOPAT | B10: =B8-B9 -> 120.9 | C10: =C8-C9 -> 146.6 | D10: =D8-D9 -> 136285 | E10: =E8-E9 -> 180268.6 | F10: =F8-F9 -> 225307.14 | G10: =G8-G9 -> 263827.39 | H10: =H8-H9 -> 298388.78 | I10: =I8-I9 -> 325552.45 | J10: =J8-J9 -> 345318.14
A11: Plus: D&A | B11: ='Historical Financials'!B$12 -> 55 | C11: ='Historical Financials'!C$12 -> 61.6 | D11: ='Historical Financials'!D$12 -> 3229 | E11: ='Capex D&A'!E$12 -> 5171.2164 | F11: ='Capex D&A'!F$12 -> 7443.1041 | G11: ='Capex D&A'!G$12 -> 10065.704 | H11: ='Capex D&A'!H$12 -> 13016.544 | I11: ='Capex D&A'!I$12 -> 15409.109 | J11: ='Capex D&A'!J$12 -> 16950.02
A12: Less: Capex | B12: ='Historical Financials'!B$17 -> 78 | C12: ='Historical Financials'!C$17 -> 82 | D12: ='Historical Financials'!D$17 -> 6572 | E12: ='Capex D&A'!E$9 -> 10342.433 | F12: ='Capex D&A'!F$9 -> 14010.549 | G12: ='Capex D&A'!G$9 -> 18012.312 | H12: ='Capex D&A'!H$9 -> 21694.241 | I12: ='Capex D&A'!I$9 -> 24514.492 | J12: ='Capex D&A'!J$9 -> 26965.941
A13: Less: Change in NWC | B13: 0 | C13: ='Historical Financials'!C$18-'Historical Financials'!B$18 -> 14 | D13: ='Historical Financials'!D$18-'Historical Financials'!C$18 -> 27407 | E13: ='Working Capital'!E$17 -> 10383.254 | F13: ='Working Capital'!F$17 -> 8049.8602 | G13: ='Working Capital'!G$17 -> 7005.2745 | H13: ='Working Capital'!H$17 -> 5906.9788 | I13: ='Working Capital'!I$17 -> 4152.8975 | J13: ='Working Capital'!J$17 -> 6303.7265
A14: Unlevered free cash flow | B14: =B10+B11-B12-B13 -> 97.9 | C14: =C10+C11-C12-C13 -> 112.2 | D14: =D10+D11-D12-D13 -> 105535 | E14: =E10+E11-E12-E13 -> 164714.13 | F14: =F10+F11-F12-F13 -> 210689.84 | G14: =G10+G11-G12-G13 -> 248875.51 | H14: =H10+H11-H12-H13 -> 283804.11 | I14: =I10+I11-I12-I13 -> 312294.17 | J14: =J10+J11-J12-J13 -> 328998.49
A15: Discount period | B15: n/a | C15: n/a | D15: n/a | E15: =IF('Control Panel'!$B$11="Yes",1-0.5,1) -> 0.5 | F15: =IF('Control Panel'!$B$11="Yes",2-0.5,2) -> 1.5 | G15: =IF('Control Panel'!$B$11="Yes",3-0.5,3) -> 2.5 | H15: =IF('Control Panel'!$B$11="Yes",4-0.5,4) -> 3.5 | I15: =IF('Control Panel'!$B$11="Yes",5-0.5,5) -> 4.5 | J15: =IF('Control Panel'!$B$11="Yes",6-0.5,6) -> 5.5
A16: Discount factor | B16: n/a | C16: n/a | D16: n/a | E16: =1/(1+'Control Panel'!$B$78)^E15 -> 0.95072112 | F16: =1/(1+'Control Panel'!$B$78)^F15 -> 0.85932891 | G16: =1/(1+'Control Panel'!$B$78)^G15 -> 0.77672218 | H16: =1/(1+'Control Panel'!$B$78)^H15 -> 0.70205638 | I16: =1/(1+'Control Panel'!$B$78)^I15 -> 0.63456815 | J16: =1/(1+'Control Panel'!$B$78)^J15 -> 0.57356752
A17: Present value of FCF | B17: n/a | C17: n/a | D17: n/a | E17: =E14*E16 -> 156597.21 | F17: =F14*F16 -> 181051.87 | G17: =G14*G16 -> 193307.13 | H17: =H14*H16 -> 199246.48 | I17: =I14*I16 -> 198171.93 | J17: =J14*J16 -> 188702.85

Sheet WACC
A1: Weighted Average Cost of Capital
A3: Cost of equity
A4: Risk-free rate | B4: ='Control Panel'!$B$69 -> 0.0463 | C4: Source / calculation basis | D4: placeholder
A5: Beta | B5: ='Control Panel'!$B$70 -> 1.35 | C5: Source / calculation basis | D5: placeholder
A6: Market risk premium | B6: ='Control Panel'!$B$71 -> 0.045 | C6: Source / calculation basis | D6: placeholder
A7: Size premium | B7: ='Control Panel'!$B$72 -> 0 | C7: Source / calculation basis | D7: placeholder
A8: Cost of equity | B8: =B4+B5*B6+B7 -> 0.10705 | C8: Source / calculation basis | D8: derived
A10: Cost of debt and capital structure
A11: Pre-tax cost of debt | B11: ='Control Panel'!$B$73 -> 0.045 | C11: Source / calculation basis | D11: placeholder
A12: Tax rate | B12: ='Tax Schedule'!J$9 -> 0.17 | C12: Source / calculation basis | D12: placeholder
A13: After-tax cost of debt | B13: =B11*(1-B12) -> 0.03735 | C13: Source / calculation basis | D13: derived
A14: Target debt / capital | B14: ='Control Panel'!$B$74 -> 0.01 | C14: Source / calculation basis | D14: placeholder
A15: Target equity / capital | B15: ='Control Panel'!$B$75 -> 0.99 | C15: Source / calculation basis | D15: placeholder
A16: WACC formula check | B16: =B14+B15 -> 1 | C16: Source / calculation basis | D16: derived
A17: Calculated WACC | B17: =B8*B15+B13*B14 -> 0.106353 | C17: Source / calculation basis | D17: derived
A19: Source notes
A20: Risk-free source | B20: ='Source Notes'!B7 -> U.S. Treasury and Codex bottom-up beta assumption
A21: Market data confidence | B21: ='Source Notes'!E7 -> Medium
A22: WACC caveat | B22: Replace illustrative assumptions with market data as of valuation date

Sheet Terminal Value
A1: Terminal Value
A3: Terminal value calculation
A4: Selected method | B4: ='Control Panel'!$B$14 -> Gordon Growth
A5: Selected WACC | B5: ='Control Panel'!$B$78 -> 0.106353
A6: Terminal growth rate | B6: ='Control Panel'!$B$83 -> 0.03
A7: Exit multiple | B7: ='Control Panel'!$B$84 -> 25
A8: Terminal EBITDA | B8: ='Margin Cost Build'!J$12 -> 432995.97
A9: Terminal FCF | B9: ='Unlevered FCF'!J$14 -> 328998.49
A10: Gordon growth terminal value | B10: =B9*(1+B6)/(B5-B6) -> 4438181.1
A11: Exit multiple terminal value | B11: =B8*B7 -> 10824899
A12: Selected terminal value | B12: =IF(B4="Gordon Growth",B10,B11) -> 4438181.1
A13: Terminal discount factor | B13: =1/(1+B5)^6 -> 0.54530276
A14: PV of terminal value | B14: =B12*B13 -> 2420152.4
A15: Implied terminal EBITDA multiple | B15: =B12/B8 -> 10.249936
A16: Implied terminal FCF yield | B16: =B9/B12 -> 0.074129126
A17: Implied perpetual growth cross-check | B17: =B5-B9/B12 -> 0.032223874
A20: Terminal value sanity checks
A21: Terminal value / enterprise value | B21: =B14/'DCF Valuation'!B$8 -> 0.68419427
A22: Growth below WACC | B22: =IF(B6<B5,"OK","FAIL") -> OK
A23: Positive selected terminal value | B23: =IF(B12>0,"OK","FAIL") -> OK

Sheet DCF Valuation
A1: DCF Valuation
A3: Enterprise value
A4: PV of forecast FCF | B4: =SUM('Unlevered FCF'!E$17:J$17) -> 1117077.5
A5: PV of terminal value | B5: ='Terminal Value'!B$14 -> 2420152.4
A6: Enterprise value | B6: =B4+B5 -> 3537229.9
A7: Terminal value % of enterprise value | B7: =B5/B6 -> 0.68419427
A8: Enterprise value check | B8: =B4+B5 -> 3537229.9
A10: EV-to-equity bridge
A11: Less: net debt | B11: ='Control Panel'!$B$85 -> -68224
A12: Less: minority interest | B12: ='Control Panel'!$B$87 -> 0
A13: Less: preferred stock | B13: ='Control Panel'!$B$88 -> 0
A14: Plus: non-operating assets | B14: ='Control Panel'!$B$89 -> 0
A15: Other equity adjustments | B15: ='Control Panel'!$B$90 -> 0
A16: Equity value | B16: =B6-B11-B12-B13+B14+B15 -> 3605453.9
A17: Diluted shares | B17: ='Control Panel'!$B$86 -> 24391
A18: Implied share price | B18: =B16/B17 -> 147.81903
A19: Current share price | B19: ='Control Panel'!$B$12 -> 211.94
A20: Upside / downside | B20: =B18/B19-1 -> -0.30254305
A21: Implied EV / EBITDA | B21: =B6/'Margin Cost Build'!J$12 -> 8.1691982
A22: Implied FCF yield | B22: ='Unlevered FCF'!J$14/B6 -> 0.093010209

Sheet Sensitivities
A1: Sensitivities
A3: Implied share price by WACC and terminal growth
A4: Terminal growth | B4: 0.075 | C4: 0.08 | D4: 0.085 | E4: 0.09 | F4: 0.095 | G4: 0.1 | H4: 0.105
A5: 0.015 | B5: =(('Unlevered FCF'!E$14/(1+B$4)^1+'Unlevered FCF'!F$14/(1+B$4)^2+'Unlevered FCF'!G$14/(1+B$4)^3+'Unlevered FCF'!H$14/(1+B$4)^4+'Unlevered FCF'!I$14/(1+B$4)^5+'Unlevered FCF'!J$14/(1+B$4)^6)+('Unlevered FCF'!J$14*(1+$A5)/(B$4-$A5))/(1+B$4)^6-'Control Panel'!$B$85-'Control Panel'!$B$87-'Control Panel'!$B$88+'Control Panel'!$B$89+'Control Panel'!$B$90)/'Control Panel'!$B$86 -> 198.99093 | C5: =(('Unlevered FCF'!E$14/(1+C$4)^1+'Unlevered FCF'!F$14/(1+C$4)^2+'Unlevered FCF'!G$14/(1+C$4)^3+'Unlevered FCF'!H$14/(1+C$4)^4+'Unlevered FCF'!I$14/(1+C$4)^5+'Unlevered FCF'!J$14/(1+C$4)^6)+('Unlevered FCF'!J$14*(1+$A5)/(C$4-$A5))/(1+C$4)^6-'Control Panel'!$B$85-'Control Panel'!$B$87-'Control Panel'!$B$88+'Control Panel'!$B$89+'Control Panel'!$B$90)/'Control Panel'!$B$86 -> 183.05375 | D5: =(('Unlevered FCF'!E$14/(1+D$4)^1+'Unlevered FCF'!F$14/(1+D$4)^2+'Unlevered FCF'!G$14/(1+D$4)^3+'Unlevered FCF'!H$14/(1+D$4)^4+'Unlevered FCF'!I$14/(1+D$4)^5+'Unlevered FCF'!J$14/(1+D$4)^6)+('Unlevered FCF'!J$14*(1+$A5)/(D$4-$A5))/(1+D$4)^6-'Control Panel'!$B$85-'Control Panel'!$B$87-'Control Panel'!$B$88+'Control Panel'!$B$89+'Control Panel'!$B$90)/'Control Panel'!$B$86 -> 169.40786 | E5: =(('Unlevered FCF'!E$14/(1+E$4)^1+'Unlevered FCF'!F$14/(1+E$4)^2+'Unlevered FCF'!G$14/(1+E$4)^3+'Unlevered FCF'!H$14/(1+E$4)^4+'Unlevered FCF'!I$14/(1+E$4)^5+'Unlevered FCF'!J$14/(1+E$4)^6)+('Unlevered FCF'!J$14*(1+$A5)/(E$4-$A5))/(1+E$4)^6-'Control Panel'!$B$85-'Control Panel'!$B$87-'Control Panel'!$B$88+'Control Panel'!$B$89+'Control Panel'!$B$90)/'Control Panel'!$B$86 -> 157.59468 | F5: =(('Unlevered FCF'!E$14/(1+F$4)^1+'Unlevered FCF'!F$14/(1+F$4)^2+'Unlevered FCF'!G$14/(1+F$4)^3+'Unlevered FCF'!H$14/(1+F$4)^4+'Unlevered FCF'!I$14/(1+F$4)^5+'Unlevered FCF'!J$14/(1+F$4)^6)+('Unlevered FCF'!J$14*(1+$A5)/(F$4-$A5))/(1+F$4)^6-'Control Panel'!$B$85-'Control Panel'!$B$87-'Control Panel'!$B$88+'Control Panel'!$B$89+'Control Panel'!$B$90)/'Control Panel'!$B$86 -> 147.27026 | G5: =(('Unlevered FCF'!E$14/(1+G$4)^1+'Unlevered FCF'!F$14/(1+G$4)^2+'Unlevered FCF'!G$14/(1+G$4)^3+'Unlevered FCF'!H$14/(1+G$4)^4+'Unlevered FCF'!I$14/(1+G$4)^5+'Unlevered FCF'!J$14/(1+G$4)^6)+('Unlevered FCF'!J$14*(1+$A5)/(G$4-$A5))/(1+G$4)^6-'Control Panel'!$B$85-'Control Panel'!$B$87-'Control Panel'!$B$88+'Control Panel'!$B$89+'Control Panel'!$B$90)/'Control Panel'!$B$86 -> 138.17161 | H5: =(('Unlevered FCF'!E$14/(1+H$4)^1+'Unlevered FCF'!F$14/(1+H$4)^2+'Unlevered FCF'!G$14/(1+H$4)^3+'Unlevered FCF'!H$14/(1+H$4)^4+'Unlevered FCF'!I$14/(1+H$4)^5+'Unlevered FCF'!J$14/(1+H$4)^6)+('Unlevered FCF'!J$14*(1+$A5)/(H$4-$A5))/(1+H$4)^6-'Control Panel'!$B$85-'Control Panel'!$B$87-'Control Panel'!$B$88+'Control Panel'!$B$89+'Control Panel'!$B$90)/'Control Panel'!$B$86 -> 130.09416
